Workbook
Name SlicerCache_Package: #N/A
Name SlicerCache_Quarter: #N/A
Name SlicerCache_Status: #N/A

Sheet Executive Summary
B2: MEGAPROJECT COMMERCIAL COST CONTROL & VARIATION ANALYTICS
B3: Executive Cost Governance | Earned Value Management (EVM) | Variation & Contingency Analytics | FY2024-2026
B5: TOTAL APPROVED BUDGET (BAC) | D5: CERTIFIED TO DATE (AC) | F5: PORTFOLIO COST VARIANCE | H5: CONTINGENCY BURN RATE | J5: PORTFOLIO CPI
B6: ='Package Variance'!F21 -> 1.1485242e+09 | D6: ='Package Variance'!I21 -> 8.2545373e+08 | F6: ='Package Variance'!J21 -> -1.2915654e+08 | H6: ='Package Variance'!P21 -> 4.3900611 | J6: ='Package Variance'!L21 -> 0.84353267
B9: Portfolio Financial Health & Earned Value Governance
B10: Key Financial Metric | C10: Portfolio Value | E10: Commercial Definition & Governance Implication
B11: Original Contract Sum (Baseline) | C11: ='Package Variance'!D21 -> 850000000 | E11: Approved baseline budget across all 10 packages
B12: Approved Variation Orders | C12: ='Package Variance'!E21 -> 2.9852415e+08 | E12: Authorized change orders added to contract sum
B13: Budget at Completion (BAC) | C13: ='Package Variance'!F21 -> 1.1485242e+09 | E13: Total authorized commercial budget baseline
B14: Earned Value (EV) | C14: ='Package Variance'!H21 -> 6.9629718e+08 | E14: Budgeted value of work physically completed to date
B15: Actual Cost / Certified to Date (AC) | C15: ='Package Variance'!I21 -> 8.2545373e+08 | E15: Gross valuation of certified work completed
B16: Cost Variance ($) [EV - AC] | C16: ='Package Variance'!J21 -> -1.2915654e+08 | E16: Positive = Favorable / Under Budget | Negative = Cost Overrun
B17: Cost Performance Index (CPI) [EV / AC] | C17: ='Package Variance'!L21 -> 0.84353267 | E17: CPI > 1.00 implies cost efficiency | < 1.00 implies cost overrun
B18: Estimate at Completion (EAC) [BAC / CPI] | C18: ='Package Variance'!M21 -> 1.4453793e+09 | E18: Projected final completion cost based on current efficiency
B19: Variance at Completion (VAC) [BAC - EAC] | C19: ='Package Variance'!N21 -> -2.9685519e+08 | E19: Projected final cost variance at project completion
B20: Total Contingency Budget Allocated | C20: ='Package Variance'!O21 -> 68000000 | E20: Contingency reserve committed for unforeseen scope changes
B21: Remaining Contingency Balance | C21: ='Package Variance'!R21 -> -2.3052415e+08 | E21: Contingency reserve minus approved variations
B22: Pending Variations Claimed Amount | C22: ='Package Variance'!Q21 -> 1.5442213e+08 | E22: Total contractor claims currently awaiting evaluation
B23: Net Contingency Exposure Risk | C23: ='Package Variance'!S21 -> 3.8494628e+08 | E23: Pending Claims minus Remaining Contingency (Deficit Risk)

Sheet Package Variance
B2: WORK PACKAGE COST VARIANCE & EARNED VALUE MANAGEMENT
B3: Dynamic SUMIFS Linked to Transaction Ledgers | BAC vs. EAC | CPI | Exposure Risk vs. Contingency
B10: Package ID | C10: Package Scope Description | D10: Original Budget | E10: Approved VOs | F10: Budget at Completion (BAC) | G10: Physical % | H10: Earned Value (EV) | I10: Certified to Date (AC) | J10: Cost Variance ($) | K10: Cost Variance (%) | L10: CPI | M10: Estimate at Completion (EAC) | N10: Variance at Completion (VAC) | O10: Contingency Budget | P10: Contingency Burn % | Q10: Pending VOs Claimed | R10: Remaining Contingency | S10: Net Exposure Risk ($) | T10: Performance Status
B11: PKG-01 | C11: Earthworks & Ground Remediation | D11: 45000000 | E11: =SUMIFS('Variation Orders'!$D$2:$D$3001, 'Variation Orders'!$B$2:$B$3001, $B11, 'Variation Orders'!$E$2:$E$3001, "Approved") -> 30235645 | F11: =$D11+$E11 -> 75235645 | G11: 0.82 | H11: =$F11*$G11 -> 61693229 | I11: =SUMIFS('Actual Expenditures'!$G$2:$G$7001, 'Actual Expenditures'!$D$2:$D$7001, $B11) -> 83313023 | J11: =$H11-$I11 -> -21619793 | K11: =IF($H11=0, 0, $J11/$H11) -> -0.3504403 | L11: =IF($I11=0, 1, $H11/$I11) -> 0.74049923 | M11: =IF($L11=0, $F11, $F11/$L11) -> 1.0160125e+08 | N11: =$F11-$M11 -> -26365602 | O11: 3600000 | P11: =IF($O11=0, 0, $E11/$O11) -> 8.3987903 | Q11: =SUMIFS('Variation Orders'!$C$2:$C$3001, 'Variation Orders'!$B$2:$B$3001, $B11, 'Variation Orders'!$E$2:$E$3001, "Pending Approval") -> 16187088 | R11: =$O11-$E11 -> -26635645 | S11: =$Q11-$R11 -> 42822734 | T11: =IF($J11>=0, "FAVORABLE / EFFICIENT", "OVER BUDGET / OVERRUN") -> OVER BUDGET / OVERRUN
B12: PKG-02 | C12: Tunnels & Underground Boring (Twin TBM) | D12: 165000000 | E12: =SUMIFS('Variation Orders'!$D$2:$D$3001, 'Variation Orders'!$B$2:$B$3001, $B12, 'Variation Orders'!$E$2:$E$3001, "Approved") -> 30263316 | F12: =$D12+$E12 -> 1.9526332e+08 | G12: 0.74 | H12: =$F12*$G12 -> 1.4449485e+08 | I12: =SUMIFS('Actual Expenditures'!$G$2:$G$7001, 'Actual Expenditures'!$D$2:$D$7001, $B12) -> 82443874 | J12: =$H12-$I12 -> 62050980 | K12: =IF($H12=0, 0, $J12/$H12) -> 0.42943384 | L12: =IF($I12=0, 1, $H12/$I12) -> 1.7526451 | M12: =IF($L12=0, $F12, $F12/$L12) -> 1.1141064e+08 | N12: =$F12-$M12 -> 83852675 | O12: 13200000 | P12: =IF($O12=0, 0, $E12/$O12) -> 2.2926754 | Q12: =SUMIFS('Variation Orders'!$C$2:$C$3001, 'Variation Orders'!$B$2:$B$3001, $B12, 'Variation Orders'!$E$2:$E$3001, "Pending Approval") -> 13177168 | R12: =$O12-$E12 -> -17063316 | S12: =$Q12-$R12 -> 30240484 | T12: =IF($J12>=0, "FAVORABLE / EFFICIENT", "OVER BUDGET / OVERRUN") -> FAVORABLE / EFFICIENT
B13: PKG-03 | C13: Elevated Viaducts & Guideway | D13: 115000000 | E13: =SUMIFS('Variation Orders'!$D$2:$D$3001, 'Variation Orders'!$B$2:$B$3001, $B13, 'Variation Orders'!$E$2:$E$3001, "Approved") -> 29054576 | F13: =$D13+$E13 -> 1.4405458e+08 | G13: 0.68 | H13: =$F13*$G13 -> 97957112 | I13: =SUMIFS('Actual Expenditures'!$G$2:$G$7001, 'Actual Expenditures'!$D$2:$D$7001, $B13) -> 84471827 | J13: =$H13-$I13 -> 13485285 | K13: =IF($H13=0, 0, $J13/$H13) -> 0.1376652 | L13: =IF($I13=0, 1, $H13/$I13) -> 1.1596424 | M13: =IF($L13=0, $F13, $F13/$L13) -> 1.2422327e+08 | N13: =$F13-$M13 -> 19831302 | O13: 9200000 | P13: =IF($O13=0, 0, $E13/$O13) -> 3.1581061 | Q13: =SUMIFS('Variation Orders'!$C$2:$C$3001, 'Variation Orders'!$B$2:$B$3001, $B13, 'Variation Orders'!$E$2:$E$3001, "Pending Approval") -> 16452949 | R13: =$O13-$E13 -> -19854576 | S13: =$Q13-$R13 -> 36307525 | T13: =IF($J13>=0, "FAVORABLE / EFFICIENT", "OVER BUDGET / OVERRUN") -> FAVORABLE / EFFICIENT
B14: PKG-04 | C14: Underground Station Structures (3 Nos) | D14: 135000000 | E14: =SUMIFS('Variation Orders'!$D$2:$D$3001, 'Variation Orders'!$B$2:$B$3001, $B14, 'Variation Orders'!$E$2:$E$3001, "Approved") -> 25681710 | F14: =$D14+$E14 -> 1.6068171e+08 | G14: 0.61 | H14: =$F14*$G14 -> 98015843 | I14: =SUMIFS('Actual Expenditures'!$G$2:$G$7001, 'Actual Expenditures'!$D$2:$D$7001, $B14) -> 81966169 | J14: =$H14-$I14 -> 16049674 | K14: =IF($H14=0, 0, $J14/$H14) -> 0.16374572 | L14: =IF($I14=0, 1, $H14/$I14) -> 1.1958085 | M14: =IF($L14=0, $F14, $F14/$L14) -> 1.3437077e+08 | N14: =$F14-$M14 -> 26310942 | O14: 10800000 | P14: =IF($O14=0, 0, $E14/$O14) -> 2.3779361 | Q14: =SUMIFS('Variation Orders'!$C$2:$C$3001, 'Variation Orders'!$B$2:$B$3001, $B14, 'Variation Orders'!$E$2:$E$3001, "Pending Approval") -> 15446977 | R14: =$O14-$E14 -> -14881710 | S14: =$Q14-$R14 -> 30328687 | T14: =IF($J14>=0, "FAVORABLE / EFFICIENT", "OVER BUDGET / OVERRUN") -> FAVORABLE / EFFICIENT
B15: PKG-05 | C15: Elevated Station Terminals & Architecture | D15: 75000000 | E15: =SUMIFS('Variation Orders'!$D$2:$D$3001, 'Variation Orders'!$B$2:$B$3001, $B15, 'Variation Orders'!$E$2:$E$3001, "Approved") -> 30552445 | F15: =$D15+$E15 -> 1.0555244e+08 | G15: 0.55 | H15: =$F15*$G15 -> 58053845 | I15: =SUMIFS('Actual Expenditures'!$G$2:$G$7001, 'Actual Expenditures'!$D$2:$D$7001, $B15) -> 82324919 | J15: =$H15-$I15 -> -24271074 | K15: =IF($H15=0, 0, $J15/$H15) -> -0.41807866 | L15: =IF($I15=0, 1, $H15/$I15) -> 0.7051795 | M15: =IF($L15=0, $F15, $F15/$L15) -> 1.4968167e+08 | N15: =$F15-$M15 -> -44129225 | O15: 6000000 | P15: =IF($O15=0, 0, $E15/$O15) -> 5.0920742 | Q15: =SUMIFS('Variation Orders'!$C$2:$C$3001, 'Variation Orders'!$B$2:$B$3001, $B15, 'Variation Orders'!$E$2:$E$3001, "Pending Approval") -> 16414904 | R15: =$O15-$E15 -> -24552445 | S15: =$Q15-$R15 -> 40967349 | T15: =IF($J15>=0, "FAVORABLE / EFFICIENT", "OVER BUDGET / OVERRUN") -> OVER BUDGET / OVERRUN
B16: PKG-06 | C16: Trackwork, Turnouts & Third Rail | D16: 58000000 | E16: =SUMIFS('Variation Orders'!$D$2:$D$3001, 'Variation Orders'!$B$2:$B$3001, $B16, 'Variation Orders'!$E$2:$E$3001, "Approved") -> 32251339 | F16: =$D16+$E16 -> 90251339 | G16: 0.52 | H16: =$F16*$G16 -> 46930696 | I16: =SUMIFS('Actual Expenditures'!$G$2:$G$7001, 'Actual Expenditures'!$D$2:$D$7001, $B16) -> 82983163 | J16: =$H16-$I16 -> -36052467 | K16: =IF($H16=0, 0, $J16/$H16) -> -0.76820653 | L16: =IF($I16=0, 1, $H16/$I16) -> 0.56554479 | M16: =IF($L16=0, $F16, $F16/$L16) -> 1.5958301e+08 | N16: =$F16-$M16 -> -69331668 | O16: 4640000 | P16: =IF($O16=0, 0, $E16/$O16) -> 6.9507195 | Q16: =SUMIFS('Variation Orders'!$C$2:$C$3001, 'Variation Orders'!$B$2:$B$3001, $B16, 'Variation Orders'!$E$2:$E$3001, "Pending Approval") -> 13606070 | R16: =$O16-$E16 -> -27611339 | S16: =$Q16-$R16 -> 41217408 | T16: =IF($J16>=0, "FAVORABLE / EFFICIENT", "OVER BUDGET / OVERRUN") -> OVER BUDGET / OVERRUN
B17: PKG-07 | C17: MEP & Environmental Control Systems | D17: 88000000 | E17: =SUMIFS('Variation Orders'!$D$2:$D$3001, 'Variation Orders'!$B$2:$B$3001, $B17, 'Variation Orders'!$E$2:$E$3001, "Approved") -> 28803348 | F17: =$D17+$E17 -> 1.1680335e+08 | G17: 0.48 | H17: =$F17*$G17 -> 56065607 | I17: =SUMIFS('Actual Expenditures'!$G$2:$G$7001, 'Actual Expenditures'!$D$2:$D$7001, $B17) -> 84406373 | J17: =$H17-$I17 -> -28340766 | K17: =IF($H17=0, 0, $J17/$H17) -> -0.50549289 | L17: =IF($I17=0, 1, $H17/$I17) -> 0.66423429 | M17: =IF($L17=0, $F17, $F17/$L17) -> 1.7584661e+08 | N17: =$F17-$M17 -> -59043262 | O17: 7040000 | P17: =IF($O17=0, 0, $E17/$O17) -> 4.0913846 | Q17: =SUMIFS('Variation Orders'!$C$2:$C$3001, 'Variation Orders'!$B$2:$B$3001, $B17, 'Variation Orders'!$E$2:$E$3001, "Pending Approval") -> 14364011 | R17: =$O17-$E17 -> -21763348 | S17: =$Q17-$R17 -> 36127359 | T17: =IF($J17>=0, "FAVORABLE / EFFICIENT", "OVER BUDGET / OVERRUN") -> OVER BUDGET / OVERRUN
B18: PKG-08 | C18: Traction Power Substation & Catenary | D18: 62000000 | E18: =SUMIFS('Variation Orders'!$D$2:$D$3001, 'Variation Orders'!$B$2:$B$3001, $B18, 'Variation Orders'!$E$2:$E$3001, "Approved") -> 29714201 | F18: =$D18+$E18 -> 91714201 | G18: 0.45 | H18: =$F18*$G18 -> 41271390 | I18: =SUMIFS('Actual Expenditures'!$G$2:$G$7001, 'Actual Expenditures'!$D$2:$D$7001, $B18) -> 82855499 | J18: =$H18-$I18 -> -41584108 | K18: =IF($H18=0, 0, $J18/$H18) -> -1.0075771 | L18: =IF($I18=0, 1, $H18/$I18) -> 0.49811287 | M18: =IF($L18=0, $F18, $F18/$L18) -> 1.8412333e+08 | N18: =$F18-$M18 -> -92409130 | O18: 4960000 | P18: =IF($O18=0, 0, $E18/$O18) -> 5.9907663 | Q18: =SUMIFS('Variation Orders'!$C$2:$C$3001, 'Variation Orders'!$B$2:$B$3001, $B18, 'Variation Orders'!$E$2:$E$3001, "Pending Approval") -> 17850091 | R18: =$O18-$E18 -> -24754201 | S18: =$Q18-$R18 -> 42604291 | T18: =IF($J18>=0, "FAVORABLE / EFFICIENT", "OVER BUDGET / OVERRUN") -> OVER BUDGET / OVERRUN
B19: PKG-09 | C19: CBTC Signalling & Telecoms | D19: 72000000 | E19: =SUMIFS('Variation Orders'!$D$2:$D$3001, 'Variation Orders'!$B$2:$B$3001, $B19, 'Variation Orders'!$E$2:$E$3001, "Approved") -> 33210788 | F19: =$D19+$E19 -> 1.0521079e+08 | G19: 0.4 | H19: =$F19*$G19 -> 42084315 | I19: =SUMIFS('Actual Expenditures'!$G$2:$G$7001, 'Actual Expenditures'!$D$2:$D$7001, $B19) -> 80896189 | J19: =$H19-$I19 -> -38811873 | K19: =IF($H19=0, 0, $J19/$H19) -> -0.92224083 | L19: =IF($I19=0, 1, $H19/$I19) -> 0.52022618 | M19: =IF($L19=0, $F19, $F19/$L19) -> 2.0224047e+08 | N19: =$F19-$M19 -> -97029684 | O19: 5760000 | P19: =IF($O19=0, 0, $E19/$O19) -> 5.7657617 | Q19: =SUMIFS('Variation Orders'!$C$2:$C$3001, 'Variation Orders'!$B$2:$B$3001, $B19, 'Variation Orders'!$E$2:$E$3001, "Pending Approval") -> 12914088 | R19: =$O19-$E19 -> -27450788 | S19: =$Q19-$R19 -> 40364876 | T19: =IF($J19>=0, "FAVORABLE / EFFICIENT", "OVER BUDGET / OVERRUN") -> OVER BUDGET / OVERRUN
B20: PKG-10 | C20: Interchange Highway & Utility Diversions | D20: 35000000 | E20: =SUMIFS('Variation Orders'!$D$2:$D$3001, 'Variation Orders'!$B$2:$B$3001, $B20, 'Variation Orders'!$E$2:$E$3001, "Approved") -> 28756785 | F20: =$D20+$E20 -> 63756785 | G20: 0.78 | H20: =$F20*$G20 -> 49730293 | I20: =SUMIFS('Actual Expenditures'!$G$2:$G$7001, 'Actual Expenditures'!$D$2:$D$7001, $B20) -> 79792693 | J20: =$H20-$I20 -> -30062400 | K20: =IF($H20=0, 0, $J20/$H20) -> -0.60450881 | L20: =IF($I20=0, 1, $H20/$I20) -> 0.62324369 | M20: =IF($L20=0, $F20, $F20/$L20) -> 1.0229832e+08 | N20: =$F20-$M20 -> -38541539 | O20: 2800000 | P20: =IF($O20=0, 0, $E20/$O20) -> 10.270281 | Q20: =SUMIFS('Variation Orders'!$C$2:$C$3001, 'Variation Orders'!$B$2:$B$3001, $B20, 'Variation Orders'!$E$2:$E$3001, "Pending Approval") -> 18008785 | R20: =$O20-$E20 -> -25956785 | S20: =$Q20-$R20 -> 43965570 | T20: =IF($J20>=0, "FAVORABLE / EFFICIENT", "OVER BUDGET / OVERRUN") -> OVER BUDGET / OVERRUN
B21: Total | C21: Portfolio Summary | D21: =SUM(D11:D20) -> 850000000 | E21: =SUM(E11:E20) -> 2.9852415e+08 | F21: =SUM(F11:F20) -> 1.1485242e+09 | G21: =H21/F21 -> 0.60625384 | H21: =SUM(H11:H20) -> 6.9629718e+08 | I21: =SUM(I11:I20) -> 8.2545373e+08 | J21: =SUM(J11:J20) -> -1.2915654e+08 | K21: =J21/H21 -> -0.18549054 | L21: =H21/I21 -> 0.84353267 | M21: =SUM(M11:M20) -> 1.4453793e+09 | N21: =SUM(N11:N20) -> -2.9685519e+08 | O21: =SUM(O11:O20) -> 68000000 | P21: =E21/O21 -> 4.3900611 | Q21: =SUM(Q11:Q20) -> 1.5442213e+08 | R21: =SUM(R11:R20) -> -2.3052415e+08 | S21: =SUM(S11:S20) -> 3.8494628e+08 | T21: =IF(J21>=0, "NET FAVORABLE", "NET PORTFOLIO OVERRUN") -> NET PORTFOLIO OVERRUN

Sheet Interactive Slicers
B2: INTERACTIVE PAYMENT & CERTIFICATE SLICER DASHBOARD
B3: Dynamic Pivot Table Driven by Connected Slicers for Package, Payment Status, and Quarter
B5: Slicer Controls & Parameter Filtering
B6: Select any Work Package or Payment Status buttons on the slicers to filter transaction totals dynamically.
B8: Total Certified ($) | C8: Column Labels
B9: Row Labels | C9: Approved Pending Payment | D9: Disputed | E9: Paid | F9: Under Review | G9: Grand Total
B10: PKG-01 | C10: 13304817 | D10: 1287885.8 | E10: 61646575 | F10: 7073744.7 | G10: 83313023
B11: PKG-02 | C11: 12845643 | D11: 2169609.2 | E11: 57184025 | F11: 10244597 | G11: 82443874
B12: PKG-03 | C12: 11747321 | D12: 2522079.5 | E12: 62241963 | F12: 7960463.6 | G12: 84471827
B13: PKG-04 | C13: 10257677 | D13: 4103925.9 | E13: 58859254 | F13: 8745310.9 | G13: 81966169
B14: PKG-05 | C14: 14830242 | D14: 2999649 | E14: 55970518 | F14: 8524510.3 | G14: 82324919
B15: PKG-06 | C15: 10915052 | D15: 3443588.4 | E15: 61878159 | F15: 6746364.2 | G15: 82983163
B16: PKG-07 | C16: 12417553 | D16: 2894960.2 | E16: 60942765 | F16: 8151093.8 | G16: 84406373
B17: PKG-08 | C17: 11831677 | D17: 3472290.9 | E17: 59724051 | F17: 7827479.9 | G17: 82855499
B18: PKG-09 | C18: 10952570 | D18: 3023804.8 | E18: 57560968 | F18: 9358846.4 | G18: 80896189
B19: PKG-10 | C19: 10567118 | D19: 3512068.5 | E19: 58262260 | F19: 7451245.8 | G19: 79792693
B20: Grand Total | C20: 1.1966967e+08 | D20: 29429862 | E20: 5.9427054e+08 | F20: 82083656 | G20: 8.2545373e+08

Sheet Actual Expenditures
A1: Expense_ID | B1: Date | C1: Item_Code | D1: Package_ID | E1: Invoice_No | F1: Certified_Qty | G1: Certified_Amount | H1: Retained_Amount | I1: Payment_Status | J1: Net_Certified_Amount | K1: Quarter
A2: EXP-000150 | B2: 2024-01-15 | C2: BOQ-PKG-10-00150 | D2: PKG-10 | E2: INV-PKG-10-011-00150 | F2: 412.18 | G2: 184944.94 | H2: 9247.25 | I2: Paid | J2: 175697.69 | K2: 2024-Q1
A3: EXP-000764 | B3: 2024-01-15 | C3: BOQ-PKG-04-00764 | D3: PKG-04 | E3: INV-PKG-04-030-00764 | F3: 421.9 | G3: 53515.85 | H3: 2675.79 | I3: Paid | J3: 50840.06 | K3: 2024-Q1
A4: EXP-000830 | B4: 2024-01-15 | C4: BOQ-PKG-10-00830 | D4: PKG-10 | E4: INV-PKG-10-026-00830 | F4: 61.49 | G4: 203959.86 | H4: 10197.99 | I4: Paid | J4: 193761.87 | K4: 2024-Q1
A5: EXP-002259 | B5: 2024-01-15 | C5: BOQ-PKG-09-00269 | D5: PKG-09 | E5: INV-PKG-09-020-02259 | F5: 275.7 | G5: 93364.63 | H5: 4668.23 | I5: Paid | J5: 88696.4 | K5: 2024-Q1
A6: EXP-002517 | B6: 2024-01-15 | C6: BOQ-PKG-07-00527 | D6: PKG-07 | E6: INV-PKG-07-033-02517 | F6: 344.61 | G6: 163507.8 | H6: 8175.39 | I6: Under Review | J6: 155332.41 | K6: 2024-Q1
A7: EXP-003106 | B7: 2024-01-15 | C7: BOQ-PKG-06-01116 | D7: PKG-06 | E7: INV-PKG-06-027-03106 | F7: 362.91 | G7: 196974.3 | H7: 9848.72 | I7: Paid | J7: 187125.58 | K7: 2024-Q1
A8: EXP-003594 | B8: 2024-01-15 | C8: BOQ-PKG-04-01604 | D8: PKG-04 | E8: INV-PKG-04-025-03594 | F8: 419.65 | G8: 127895.21 | H8: 6394.76 | I8: Paid | J8: 121500.45 | K8: 2024-Q1
A9: EXP-004595 | B9: 2024-01-15 | C9: BOQ-PKG-05-00615 | D9: PKG-05 | E9: INV-PKG-05-011-04595 | F9: 315.16 | G9: 125984.27 | H9: 6299.21 | I9: Paid | J9: 119685.06 | K9: 2024-Q1
A10: EXP-004653 | B10: 2024-01-15 | C10: BOQ-PKG-03-00673 | D10: PKG-03 | E10: INV-PKG-03-034-04653 | F10: 405.2 | G10: 40619.95 | H10: 2031 | I10: Paid | J10: 38588.95 | K10: 2024-Q1
A11: EXP-005834 | B11: 2024-01-15 | C11: BOQ-PKG-04-01854 | D11: PKG-04 | E11: INV-PKG-04-025-05834 | F11: 119.92 | G11: 194456.84 | H11: 9722.84 | I11: Paid | J11: 184734 | K11: 2024-Q1
A12: EXP-006034 | B12: 2024-01-15 | C12: BOQ-PKG-04-00064 | D12: PKG-04 | E12: INV-PKG-04-015-06034 | F12: 414.83 | G12: 184026.33 | H12: 9201.32 | I12: Paid | J12: 174825.01 | K12: 2024-Q1
A13: EXP-002473 | B13: 2024-01-16 | C13: BOQ-PKG-03-00483 | D13: PKG-03 | E13: INV-PKG-03-024-02473 | F13: 330.64 | G13: 167470.75 | H13: 8373.54 | I13: Paid | J13: 159097.21 | K13: 2024-Q1
... A7001: EXP-005460 | B7001: 2026-08-21 | C7001: BOQ-PKG-10-01480 | D7001: PKG-10 | E7001: INV-PKG-10-001-05460 | F7001: 148.47 | G7001: 186504.77 | H7001: 9325.24 | I7001: Disputed | J7001: 177179.53 | K7001: 2026-Q3

Sheet Variation Orders
A1: VO_Number | B1: Package_ID | C1: Claim_Amount | D1: Approved_Amount | E1: Status | F1: Time_Impact_Days | G1: Submission_Date | H1: Decision_Date | I1: VO_Title
A2: VO-PKG-03-00943 | B2: PKG-03 | C2: 44101.84 | D2: 38028.07 | E2: Approved | F2: 6 | G2: 2024-02-14 | H2: 2024-03-24 | I2: Viaduct pier foundation redesign due to utility clash
A3: VO-PKG-04-02234 | B3: PKG-04 | C3: 25015.16 | D3: 20578.97 | E3: Approved | F3: 43 | G3: 2024-02-14 | H3: 2024-04-10 | I3: Station box diaphragm wall water ingress mitigation
A4: VO-PKG-05-02575 | B4: PKG-05 | C4: 349946.84 | D4: 332320.54 | E4: Approved | F4: 55 | G4: 2024-02-14 | H4: 2024-04-05 | I4: HV substation redundancy transformer capacity upgrade
A5: VO-PKG-07-02927 | B5: PKG-07 | C5: 220359.71 | D5: 202354.05 | E5: Approved | F5: 14 | G5: 2024-02-14 | H5: 2024-03-05 | I5: Fiber optic telemetry routing realignment along guideway
A6: VO-PKG-02-01712 | B6: PKG-02 | C6: 181127.81 | D6: 158820.2 | E6: Approved | F6: 34 | G6: 2024-02-15 | H6: 2024-03-15 | I6: TBM Cutterhead refurbishment and rock fissure sealing
A7: VO-PKG-02-02202 | B7: PKG-02 | C7: 124753.67 | D7: 102141.55 | E7: Approved | F7: 11 | G7: 2024-02-15 | H7: 2024-04-04 | I7: TBM Cutterhead refurbishment and rock fissure sealing
A8: VO-PKG-02-02732 | B8: PKG-02 | C8: 42866.59 | D8: 38581.78 | E8: Approved | F8: 55 | G8: 2024-02-15 | H8: 2024-03-21 | I8: TBM Cutterhead refurbishment and rock fissure sealing
A9: VO-PKG-04-02094 | B9: PKG-04 | C9: 64374.99 | D9: 0 | E9: Pending Approval | F9: 12 | G9: 2024-02-15 | I9: Station box diaphragm wall water ingress mitigation
A10: VO-PKG-08-02578 | B10: PKG-08 | C10: 49052.14 | D10: 41327.53 | E10: Approved | F10: 19 | G10: 2024-02-15 | H10: 2024-03-15 | I10: Track vibration damping rubber pads acoustic upgrade
A11: VO-PKG-04-02014 | B11: PKG-04 | C11: 80299.66 | D11: 71947.96 | E11: Approved | F11: 24 | G11: 2024-02-16 | H11: 2024-03-06 | I11: Station box diaphragm wall water ingress mitigation
A12: VO-PKG-08-00568 | B12: PKG-08 | C12: 47250.63 | D12: 45844.45 | E12: Approved | F12: 11 | G12: 2024-02-16 | H12: 2024-03-06 | I12: Track vibration damping rubber pads acoustic upgrade
A13: VO-PKG-08-02948 | B13: PKG-08 | C13: 179203.82 | D13: 0 | E13: Pending Approval | F13: 43 | G13: 2024-02-16 | I13: Track vibration damping rubber pads acoustic upgrade
A14: VO-PKG-10-01920 | B14: PKG-10 | C14: 62643.27 | D14: 56066.54 | E14: Approved | F14: 57 | G14: 2024-02-17 | H14: 2024-03-13 | I14: HVAC chilled water pipe rerouting around station concourse
A15: VO-PKG-01-01641 | B15: PKG-01 | C15: 272202.42 | D15: 263231.7 | E15: Approved | F15: 54 | G15: 2024-02-18 | H15: 2024-03-07 | I15: Unforeseen soft ground stabilization and grouting
A16: VO-PKG-02-02992 | B16: PKG-02 | C16: 213357.33 | D16: 0 | E16: Pending Approval | F16: 30 | G16: 2024-02-18 | I16: TBM Cutterhead refurbishment and rock fissure sealing
A17: VO-PKG-04-02354 | B17: PKG-04 | C17: 321781.59 | D17: 0 | E17: Pending Approval | F17: 10 | G17: 2024-02-18 | I17: Station box diaphragm wall water ingress mitigation
A18: VO-PKG-07-00097 | B18: PKG-07 | C18: 243189.81 | D18: 211544.4 | E18: Approved | F18: 14 | G18: 2024-02-18 | H18: 2024-03-17 | I18: Fiber optic telemetry routing realignment along guideway
A19: VO-PKG-07-01877 | B19: PKG-07 | C19: 27045.71 | D19: 0 | E19: Rejected | F19: 0 | G19: 2024-02-18 | H19: 2024-03-03 | I19: Fiber optic telemetry routing realignment along guideway
A20: VO-PKG-10-01360 | B20: PKG-10 | C20: 331203.4 | D20: 314960.77 | E20: Approved | F20: 6 | G20: 2024-02-18 | H20: 2024-03-30 | I20: HVAC chilled water pipe rerouting around station concourse
A21: VO-PKG-06-00416 | B21: PKG-06 | C21: 103344.99 | D21: 88017.13 | E21: Approved | F21: 38 | G21: 2024-02-19 | H21: 2024-04-12 | I21: Additional smoke evacuation shafts in underground platforms
A22: VO-PKG-09-01489 | B22: PKG-09 | C22: 245078.28 | D22: 0 | E22: Rejected | F22: 0 | G22: 2024-02-19 | H22: 2024-03-03 | I22: Drainage box culvert capacity expansion for 100-year flood event
A23: VO-PKG-03-00373 | B23: PKG-03 | C23: 133858.19 | D23: 124321.66 | E23: Approved | F23: 8 | G23: 2024-02-20 | H23: 2024-04-07 | I23: Viaduct pier foundation redesign due to utility clash
A24: VO-PKG-05-01085 | B24: PKG-05 | C24: 198848.58 | D24: 183410.42 | E24: Approved | F24: 50 | G24: 2024-02-20 | H24: 2024-04-17 | I24: HV substation redundancy transformer capacity upgrade
A25: VO-PKG-06-02006 | B25: PKG-06 | C25: 199870.48 | D25: 182018.01 | E25: Approved | F25: 58 | G25: 2024-02-20 | H25: 2024-03-09 | I25: Additional smoke evacuation shafts in underground platforms
A26: VO-PKG-09-01899 | B26: PKG-09 | C26: 21499.01 | D26: 0 | E26: Pending Approval | F26: 22 | G26: 2024-02-20 | I26: Drainage box culvert capacity expansion for 100-year flood event
A27: VO-PKG-01-01891 | B27: PKG-01 | C27: 87162.1 | D27: 74742.23 | E27: Approved | F27: 56 | G27: 2024-02-21 | H27: 2024-03-11 | I27: Unforeseen soft ground stabilization and grouting
A28: VO-PKG-02-01292 | B28: PKG-02 | C28: 319614.27 | D28: 281772.6 | E28: Approved | F28: 47 | G28: 2024-02-21 | H28: 2024-04-16 | I28: TBM Cutterhead refurbishment and rock fissure sealing
A29: VO-PKG-04-01084 | B29: PKG-04 | C29: 272503.13 | D29: 256697.87 | E29: Approved | F29: 26 | G29: 2024-02-21 | H29: 2024-03-29 | I29: Station box diaphragm wall water ingress mitigation
A30: VO-PKG-01-02081 | B30: PKG-01 | C30: 37990.33 | D30: 32740.41 | E30: Approved | F30: 16 | G30: 2024-02-22 | H30: 2024-03-31 | I30: Unforeseen soft ground stabilization and grouting
A31: VO-PKG-04-01004 | B31: PKG-04 | C31: 65425.45 | D31: 0 | E31: Rejected | F31: 0 | G31: 2024-02-22 | H31: 2024-03-16 | I31: Station box diaphragm wall water ingress mitigation
A32: VO-PKG-04-01404 | B32: PKG-04 | C32: 330800.21 | D32: 271490.87 | E32: Approved | F32: 37 | G32: 2024-02-22 | H32: 2024-04-17 | I32: Station box diaphragm wall water ingress mitigation
A33: VO-PKG-06-00306 | B33: PKG-06 | C33: 173521.46 | D33: 166981.03 | E33: Approved | F33: 47 | G33: 2024-02-22 | H33: 2024-04-20 | I33: Additional smoke evacuation shafts in underground platforms
A34: VO-PKG-08-02998 | B34: PKG-08 | C34: 279140.08 | D34: 225597.88 | E34: Approved | F34: 46 | G34: 2024-02-22 | H34: 2024-03-25 | I34: Track vibration damping rubber pads acoustic upgrade
A35: VO-PKG-03-02503 | B35: PKG-03 | C35: 134826.5 | D35: 111116.1 | E35: Approved | F35: 6 | G35: 2024-02-23 | H35: 2024-04-06 | I35: Viaduct pier foundation redesign due to utility clash
A36: VO-PKG-08-02098 | B36: PKG-08 | C36: 300561.83 | D36: 257292.48 | E36: Approved | F36: 6 | G36: 2024-02-23 | H36: 2024-04-18 | I36: Track vibration damping rubber pads acoustic upgrade
A37: VO-PKG-01-01451 | B37: PKG-01 | C37: 71516.84 | D37: 67176.31 | E37: Approved | F37: 14 | G37: 2024-02-24 | H37: 2024-03-18 | I37: Unforeseen soft ground stabilization and grouting
A38: VO-PKG-01-01541 | B38: PKG-01 | C38: 303769.83 | D38: 290924.5 | E38: Approved | F38: 32 | G38: 2024-02-24 | H38: 2024-04-02 | I38: Unforeseen soft ground stabilization and grouting
... A40: VO-PKG-09-00909 | B40: PKG-09 | C40: 178416.17 | D40: 166280.72 | E40: Approved | F40: 57 | G40: 2024-02-24 | H40: 2024-03-11 | I40: Drainage box culvert capacity expansion for 100-year flood event
A41: VO-PKG-02-02692 | B41: PKG-02 | C41: 58618.35 | D41: 0 | E41: Pending Approval | F41: 26 | G41: 2024-02-25 | I41: TBM Cutterhead refurbishment and rock fissure sealing
...

Sheet Quality Control & Audit
B2: QUALITY CONTROL & MATHEMATICAL RECONCILIATION AUDIT
B3: Reconciliation Proof: Raw CSV Certified Total = Excel Certified Total ($0.00 Discrepancy)
B5: Audit Verification Scorecard
B6: Audit Category | C6: Verification Item | D6: Expected (Raw CSV / DB) | E6: Actual (Excel Model) | F6: Variance Delta | G6: Status
B7: Financial Reconciliation | C7: Total Certified Sum ($) | D7: 8.2545373e+08 | E7: ='Package Variance'!I21 -> 8.2545373e+08 | F7: =E7-D7 -> 0 | G7: VERIFIED PARITY
B8: Integrity Check | C8: Expenditures Transaction Count | D8: 7000 | E8: =COUNTA('Actual Expenditures'!A2:A7001) -> 7000 | F8: =E8-D8 -> 0 | G8: EXACT MATCH
B9: Integrity Check | C9: Variation Orders Transaction Count | D9: 3000 | E9: =COUNTA('Variation Orders'!A2:A3001) -> 3000 | F9: =E9-D9 -> 0 | G9: EXACT MATCH
B10: Integrity Check | C10: Work Packages Count | D10: 10 | E10: =COUNTA('Package Variance'!B11:B20) -> 10 | F10: =E10-D10 -> 0 | G10: EXACT MATCH
B11: Integrity Check | C11: Total Baseline Budget ($) | D11: 850000000 | E11: ='Package Variance'!D21 -> 850000000 | F11: =E11-D11 -> 0 | G11: EXACT MATCH
B12: Integrity Check | C12: Total Contingency Budget ($) | D12: 68000000 | E12: ='Package Variance'!O21 -> 68000000 | F12: =E12-D12 -> 0 | G12: EXACT MATCH

Sheet Package Dashboard
B2: WORK PACKAGE PERFORMANCE DASHBOARD
B3: Sheets 2–5 dashboard series | Portfolio EVM, forecast and exposure by work package
B5: BUDGET AT COMPLETION | E5: ESTIMATE AT COMPLETION | H5: VARIANCE AT COMPLETION | K5: PORTFOLIO CPI
B6: ='Package Variance'!F21 -> 1.1485242e+09 | E6: ='Package Variance'!M21 -> 1.4453793e+09 | H6: ='Package Variance'!N21 -> -2.9685519e+08 | K6: ='Package Variance'!L21 -> 0.84353267
B9: PERFORMANCE VISUALS
B24: LIVE ANALYSIS TABLES
B25: Package | C25: BAC | D25: EAC | F25: Package | G25: CPI | I25: Package | J25: Net Exposure
B26: ='Package Variance'!B11 -> PKG-01 | C26: ='Package Variance'!F11 -> 75235645 | D26: ='Package Variance'!M11 -> 1.0160125e+08 | F26: ='Package Variance'!B11 -> PKG-01 | G26: ='Package Variance'!L11 -> 0.74049923 | I26: ='Package Variance'!B11 -> PKG-01 | J26: ='Package Variance'!S11 -> 42822734
B27: ='Package Variance'!B12 -> PKG-02 | C27: ='Package Variance'!F12 -> 1.9526332e+08 | D27: ='Package Variance'!M12 -> 1.1141064e+08 | F27: ='Package Variance'!B12 -> PKG-02 | G27: ='Package Variance'!L12 -> 1.7526451 | I27: ='Package Variance'!B12 -> PKG-02 | J27: ='Package Variance'!S12 -> 30240484
B28: ='Package Variance'!B13 -> PKG-03 | C28: ='Package Variance'!F13 -> 1.4405458e+08 | D28: ='Package Variance'!M13 -> 1.2422327e+08 | F28: ='Package Variance'!B13 -> PKG-03 | G28: ='Package Variance'!L13 -> 1.1596424 | I28: ='Package Variance'!B13 -> PKG-03 | J28: ='Package Variance'!S13 -> 36307525
B29: ='Package Variance'!B14 -> PKG-04 | C29: ='Package Variance'!F14 -> 1.6068171e+08 | D29: ='Package Variance'!M14 -> 1.3437077e+08 | F29: ='Package Variance'!B14 -> PKG-04 | G29: ='Package Variance'!L14 -> 1.1958085 | I29: ='Package Variance'!B14 -> PKG-04 | J29: ='Package Variance'!S14 -> 30328687
B30: ='Package Variance'!B15 -> PKG-05 | C30: ='Package Variance'!F15 -> 1.0555244e+08 | D30: ='Package Variance'!M15 -> 1.4968167e+08 | F30: ='Package Variance'!B15 -> PKG-05 | G30: ='Package Variance'!L15 -> 0.7051795 | I30: ='Package Variance'!B15 -> PKG-05 | J30: ='Package Variance'!S15 -> 40967349
B31: ='Package Variance'!B16 -> PKG-06 | C31: ='Package Variance'!F16 -> 90251339 | D31: ='Package Variance'!M16 -> 1.5958301e+08 | F31: ='Package Variance'!B16 -> PKG-06 | G31: ='Package Variance'!L16 -> 0.56554479 | I31: ='Package Variance'!B16 -> PKG-06 | J31: ='Package Variance'!S16 -> 41217408
B32: ='Package Variance'!B17 -> PKG-07 | C32: ='Package Variance'!F17 -> 1.1680335e+08 | D32: ='Package Variance'!M17 -> 1.7584661e+08 | F32: ='Package Variance'!B17 -> PKG-07 | G32: ='Package Variance'!L17 -> 0.66423429 | I32: ='Package Variance'!B17 -> PKG-07 | J32: ='Package Variance'!S17 -> 36127359
B33: ='Package Variance'!B18 -> PKG-08 | C33: ='Package Variance'!F18 -> 91714201 | D33: ='Package Variance'!M18 -> 1.8412333e+08 | F33: ='Package Variance'!B18 -> PKG-08 | G33: ='Package Variance'!L18 -> 0.49811287 | I33: ='Package Variance'!B18 -> PKG-08 | J33: ='Package Variance'!S18 -> 42604291
B34: ='Package Variance'!B19 -> PKG-09 | C34: ='Package Variance'!F19 -> 1.0521079e+08 | D34: ='Package Variance'!M19 -> 2.0224047e+08 | F34: ='Package Variance'!B19 -> PKG-09 | G34: ='Package Variance'!L19 -> 0.52022618 | I34: ='Package Variance'!B19 -> PKG-09 | J34: ='Package Variance'!S19 -> 40364876
B35: ='Package Variance'!B20 -> PKG-10 | C35: ='Package Variance'!F20 -> 63756785 | D35: ='Package Variance'!M20 -> 1.0229832e+08 | F35: ='Package Variance'!B20 -> PKG-10 | G35: ='Package Variance'!L20 -> 0.62324369 | I35: ='Package Variance'!B20 -> PKG-10 | J35: ='Package Variance'!S20 -> 43965570

Sheet Payment Dashboard
B2: PAYMENT & CERTIFICATE DASHBOARD
B3: Payment status composition and package-level certified values from the interactive summary
B5: TOTAL CERTIFIED | E5: PAID | H5: PENDING PAYMENT | K5: UNDER REVIEW
B6: ='Interactive Slicers'!G20 -> 8.2545373e+08 | E6: ='Interactive Slicers'!E20 -> 5.9427054e+08 | H6: ='Interactive Slicers'!C20 -> 1.1966967e+08 | K6: ='Interactive Slicers'!F20 -> 82083656
B9: PERFORMANCE VISUALS
B24: LIVE ANALYSIS TABLES
B25: Payment Status | C25: Certified Amount | E25: Package | F25: Pending | G25: Disputed | H25: Paid | I25: Under Review | J25: Total
B26: Approved Pending Payment | C26: ='Interactive Slicers'!C20 -> 1.1966967e+08 | E26: ='Interactive Slicers'!B10 -> PKG-01 | F26: ='Interactive Slicers'!C10 -> 13304817 | G26: ='Interactive Slicers'!D10 -> 1287885.8 | H26: ='Interactive Slicers'!E10 -> 61646575 | I26: ='Interactive Slicers'!F10 -> 7073744.7 | J26: ='Interactive Slicers'!G10 -> 83313023
B27: Disputed | C27: ='Interactive Slicers'!D20 -> 29429862 | E27: ='Interactive Slicers'!B11 -> PKG-02 | F27: ='Interactive Slicers'!C11 -> 12845643 | G27: ='Interactive Slicers'!D11 -> 2169609.2 | H27: ='Interactive Slicers'!E11 -> 57184025 | I27: ='Interactive Slicers'!F11 -> 10244597 | J27: ='Interactive Slicers'!G11 -> 82443874
B28: Paid | C28: ='Interactive Slicers'!E20 -> 5.9427054e+08 | E28: ='Interactive Slicers'!B12 -> PKG-03 | F28: ='Interactive Slicers'!C12 -> 11747321 | G28: ='Interactive Slicers'!D12 -> 2522079.5 | H28: ='Interactive Slicers'!E12 -> 62241963 | I28: ='Interactive Slicers'!F12 -> 7960463.6 | J28: ='Interactive Slicers'!G12 -> 84471827
B29: Under Review | C29: ='Interactive Slicers'!F20 -> 82083656 | E29: ='Interactive Slicers'!B13 -> PKG-04 | F29: ='Interactive Slicers'!C13 -> 10257677 | G29: ='Interactive Slicers'!D13 -> 4103925.9 | H29: ='Interactive Slicers'!E13 -> 58859254 | I29: ='Interactive Slicers'!F13 -> 8745310.9 | J29: ='Interactive Slicers'!G13 -> 81966169
E30: ='Interactive Slicers'!B14 -> PKG-05 | F30: ='Interactive Slicers'!C14 -> 14830242 | G30: ='Interactive Slicers'!D14 -> 2999649 | H30: ='Interactive Slicers'!E14 -> 55970518 | I30: ='Interactive Slicers'!F14 -> 8524510.3 | J30: ='Interactive Slicers'!G14 -> 82324919
E31: ='Interactive Slicers'!B15 -> PKG-06 | F31: ='Interactive Slicers'!C15 -> 10915052 | G31: ='Interactive Slicers'!D15 -> 3443588.4 | H31: ='Interactive Slicers'!E15 -> 61878159 | I31: ='Interactive Slicers'!F15 -> 6746364.2 | J31: ='Interactive Slicers'!G15 -> 82983163
E32: ='Interactive Slicers'!B16 -> PKG-07 | F32: ='Interactive Slicers'!C16 -> 12417553 | G32: ='Interactive Slicers'!D16 -> 2894960.2 | H32: ='Interactive Slicers'!E16 -> 60942765 | I32: ='Interactive Slicers'!F16 -> 8151093.8 | J32: ='Interactive Slicers'!G16 -> 84406373
E33: ='Interactive Slicers'!B17 -> PKG-08 | F33: ='Interactive Slicers'!C17 -> 11831677 | G33: ='Interactive Slicers'!D17 -> 3472290.9 | H33: ='Interactive Slicers'!E17 -> 59724051 | I33: ='Interactive Slicers'!F17 -> 7827479.9 | J33: ='Interactive Slicers'!G17 -> 82855499
E34: ='Interactive Slicers'!B18 -> PKG-09 | F34: ='Interactive Slicers'!C18 -> 10952570 | G34: ='Interactive Slicers'!D18 -> 3023804.8 | H34: ='Interactive Slicers'!E18 -> 57560968 | I34: ='Interactive Slicers'!F18 -> 9358846.4 | J34: ='Interactive Slicers'!G18 -> 80896189
E35: ='Interactive Slicers'!B19 -> PKG-10 | F35: ='Interactive Slicers'!C19 -> 10567118 | G35: ='Interactive Slicers'!D19 -> 3512068.5 | H35: ='Interactive Slicers'!E19 -> 58262260 | I35: ='Interactive Slicers'!F19 -> 7451245.8 | J35: ='Interactive Slicers'!G19 -> 79792693

Sheet Expenditure Dashboard
B2: ACTUAL EXPENDITURE DASHBOARD
B3: Transaction-level certified cost, retention, payment status and quarterly delivery trend
B5: CERTIFIED AMOUNT | E5: NET CERTIFIED | H5: RETENTION HELD | K5: TRANSACTIONS
B6: =SUM(Table_Expenditures[Certified_Amount]) -> 8.2545373e+08 | E6: =SUM(Table_Expenditures[Net_Certified_Amount]) -> 7.8418104e+08 | H6: =SUM(Table_Expenditures[Retained_Amount]) -> 41272687 | K6: =ROWS(Table_Expenditures[Expense_ID]) -> 7000
B9: PERFORMANCE VISUALS
B24: LIVE ANALYSIS TABLES
B25: Quarter | C25: Net Certified | E25: Package | F25: Net Certified | H25: Payment Status | I25: Net Certified
B26: 2024-Q1 | C26: =SUMIFS(Table_Expenditures[Net_Certified_Amount],Table_Expenditures[Quarter],B26) -> 64314001 | E26: PKG-01 | F26: =SUMIFS(Table_Expenditures[Net_Certified_Amount],Table_Expenditures[Package_ID],E26) -> 79147371 | H26: Approved Pending Payment | I26: =SUMIFS(Table_Expenditures[Net_Certified_Amount],Table_Expenditures[Payment_Status],H26) -> 1.1368619e+08
B27: 2024-Q2 | C27: =SUMIFS(Table_Expenditures[Net_Certified_Amount],Table_Expenditures[Quarter],B27) -> 75038804 | E27: PKG-02 | F27: =SUMIFS(Table_Expenditures[Net_Certified_Amount],Table_Expenditures[Package_ID],E27) -> 78321680 | H27: Disputed | I27: =SUMIFS(Table_Expenditures[Net_Certified_Amount],Table_Expenditures[Payment_Status],H27) -> 27958369
B28: 2024-Q3 | C28: =SUMIFS(Table_Expenditures[Net_Certified_Amount],Table_Expenditures[Quarter],B28) -> 78205265 | E28: PKG-03 | F28: =SUMIFS(Table_Expenditures[Net_Certified_Amount],Table_Expenditures[Package_ID],E28) -> 80248235 | H28: Paid | I28: =SUMIFS(Table_Expenditures[Net_Certified_Amount],Table_Expenditures[Payment_Status],H28) -> 5.6455701e+08
B29: 2024-Q4 | C29: =SUMIFS(Table_Expenditures[Net_Certified_Amount],Table_Expenditures[Quarter],B29) -> 76182992 | E29: PKG-04 | F29: =SUMIFS(Table_Expenditures[Net_Certified_Amount],Table_Expenditures[Package_ID],E29) -> 77867860 | H29: Under Review | I29: =SUMIFS(Table_Expenditures[Net_Certified_Amount],Table_Expenditures[Payment_Status],H29) -> 77979474
B30: 2025-Q1 | C30: =SUMIFS(Table_Expenditures[Net_Certified_Amount],Table_Expenditures[Quarter],B30) -> 78563791 | E30: PKG-05 | F30: =SUMIFS(Table_Expenditures[Net_Certified_Amount],Table_Expenditures[Package_ID],E30) -> 78208673
B31: 2025-Q2 | C31: =SUMIFS(Table_Expenditures[Net_Certified_Amount],Table_Expenditures[Quarter],B31) -> 76809428 | E31: PKG-06 | F31: =SUMIFS(Table_Expenditures[Net_Certified_Amount],Table_Expenditures[Package_ID],E31) -> 78834005
B32: 2025-Q3 | C32: =SUMIFS(Table_Expenditures[Net_Certified_Amount],Table_Expenditures[Quarter],B32) -> 70661776 | E32: PKG-07 | F32: =SUMIFS(Table_Expenditures[Net_Certified_Amount],Table_Expenditures[Package_ID],E32) -> 80186054
B33: 2025-Q4 | C33: =SUMIFS(Table_Expenditures[Net_Certified_Amount],Table_Expenditures[Quarter],B33) -> 74441208 | E33: PKG-08 | F33: =SUMIFS(Table_Expenditures[Net_Certified_Amount],Table_Expenditures[Package_ID],E33) -> 78712724
B34: 2026-Q1 | C34: =SUMIFS(Table_Expenditures[Net_Certified_Amount],Table_Expenditures[Quarter],B34) -> 74812991 | E34: PKG-09 | F34: =SUMIFS(Table_Expenditures[Net_Certified_Amount],Table_Expenditures[Package_ID],E34) -> 76851379
B35: 2026-Q2 | C35: =SUMIFS(Table_Expenditures[Net_Certified_Amount],Table_Expenditures[Quarter],B35) -> 72295348 | E35: PKG-10 | F35: =SUMIFS(Table_Expenditures[Net_Certified_Amount],Table_Expenditures[Package_ID],E35) -> 75803058
B36: 2026-Q3 | C36: =SUMIFS(Table_Expenditures[Net_Certified_Amount],Table_Expenditures[Quarter],B36) -> 42855436

Sheet Variation Dashboard
B2: VARIATION ORDER DASHBOARD
B3: Claims, approvals, time impact and commercial exposure across all work packages
B5: TOTAL CLAIMED | E5: TOTAL APPROVED | H5: APPROVAL VALUE RATE | K5: AVG TIME IMPACT
B6: =SUM(Table_VariationOrders[Claim_Amount]) -> 5.4950344e+08 | E6: =SUM(Table_VariationOrders[Approved_Amount]) -> 2.9852415e+08 | H6: =IFERROR(SUM(Table_VariationOrders[Approved_Amount])/SUM(Table_VariationOrders[Claim_Amount]),0) -> 0.54326166 | K6: =AVERAGE(Table_VariationOrders[Time_Impact_Days]) -> 25.270333
B9: PERFORMANCE VISUALS
B24: LIVE ANALYSIS TABLES
B25: Package | C25: Claimed | D25: Approved | F25: Status | G25: Claimed Amount | I25: Status | J25: VO Count
B26: PKG-01 | C26: =SUMIFS(Table_VariationOrders[Claim_Amount],Table_VariationOrders[Package_ID],B26) -> 55827333 | D26: =SUMIFS(Table_VariationOrders[Approved_Amount],Table_VariationOrders[Package_ID],B26) -> 30235645 | F26: Approved | G26: =SUMIFS(Table_VariationOrders[Claim_Amount],Table_VariationOrders[Status],F26) -> 3.3442658e+08 | I26: Approved | J26: =COUNTIF(Table_VariationOrders[Status],I26) -> 1823
B27: PKG-02 | C27: =SUMIFS(Table_VariationOrders[Claim_Amount],Table_VariationOrders[Package_ID],B27) -> 52220147 | D27: =SUMIFS(Table_VariationOrders[Approved_Amount],Table_VariationOrders[Package_ID],B27) -> 30263316 | F27: Pending Approval | G27: =SUMIFS(Table_VariationOrders[Claim_Amount],Table_VariationOrders[Status],F27) -> 1.5442213e+08 | I27: Pending Approval | J27: =COUNTIF(Table_VariationOrders[Status],I27) -> 844
B28: PKG-03 | C28: =SUMIFS(Table_VariationOrders[Claim_Amount],Table_VariationOrders[Package_ID],B28) -> 56016450 | D28: =SUMIFS(Table_VariationOrders[Approved_Amount],Table_VariationOrders[Package_ID],B28) -> 29054576 | F28: Rejected | G28: =SUMIFS(Table_VariationOrders[Claim_Amount],Table_VariationOrders[Status],F28) -> 60654723 | I28: Rejected | J28: =COUNTIF(Table_VariationOrders[Status],I28) -> 333
B29: PKG-04 | C29: =SUMIFS(Table_VariationOrders[Claim_Amount],Table_VariationOrders[Package_ID],B29) -> 53779837 | D29: =SUMIFS(Table_VariationOrders[Approved_Amount],Table_VariationOrders[Package_ID],B29) -> 25681710
B30: PKG-05 | C30: =SUMIFS(Table_VariationOrders[Claim_Amount],Table_VariationOrders[Package_ID],B30) -> 57457708 | D30: =SUMIFS(Table_VariationOrders[Approved_Amount],Table_VariationOrders[Package_ID],B30) -> 30552445
B31: PKG-06 | C31: =SUMIFS(Table_VariationOrders[Claim_Amount],Table_VariationOrders[Package_ID],B31) -> 53373047 | D31: =SUMIFS(Table_VariationOrders[Approved_Amount],Table_VariationOrders[Package_ID],B31) -> 32251339
B32: PKG-07 | C32: =SUMIFS(Table_VariationOrders[Claim_Amount],Table_VariationOrders[Package_ID],B32) -> 53194267 | D32: =SUMIFS(Table_VariationOrders[Approved_Amount],Table_VariationOrders[Package_ID],B32) -> 28803348
B33: PKG-08 | C33: =SUMIFS(Table_VariationOrders[Claim_Amount],Table_VariationOrders[Package_ID],B33) -> 55203898 | D33: =SUMIFS(Table_VariationOrders[Approved_Amount],Table_VariationOrders[Package_ID],B33) -> 29714201
B34: PKG-09 | C34: =SUMIFS(Table_VariationOrders[Claim_Amount],Table_VariationOrders[Package_ID],B34) -> 57642234 | D34: =SUMIFS(Table_VariationOrders[Approved_Amount],Table_VariationOrders[Package_ID],B34) -> 33210788
B35: PKG-10 | C35: =SUMIFS(Table_VariationOrders[Claim_Amount],Table_VariationOrders[Package_ID],B35) -> 54788516 | D35: =SUMIFS(Table_VariationOrders[Approved_Amount],Table_VariationOrders[Package_ID],B35) -> 28756785
